Workbook

Sheet Fillout Waung-K results
A1: Submission ID | B1: Last updated | C1: Submission started | D1: Status | E1: Current step | F1: Kode Petugas Pendataan | G1: Tanggal Pendataan | H1: Nama Petugas Pendataan | I1: 1.a. Nama Kepala Keluarga | J1: 1.b. Nomor KK | K1: 1.c. Upload Foto KK | L1: 2. Nama Pemberi Informasi | M1: 3.a. Alamat Domisili | N1: 3.b. RT/RW | O1: 4.a. Apakah alamat tersebut sesuai dengan alamat pada KK? | P1: 4.b. Tuliskan alamat pada KK | Q1: 5. Berapa jumlah KK yang tinggal dalam 1 rumah tempat tinggal | R1: 6. Status kepemilikan bangunan tempat tinggal yang ditempati | S1: 7. Jika tempat tinggal milik sendiri, apa jenis bukti kepemilikan tanah bangunan tempat tinggal ini? | T1: 8. Jika Kontrak/Sewa, berapa nilai kontrak sebulan? | U1: 9.Berapa luas lantai bangunan tempat tinggal | V1: 10.a. Apa bahan bangunan utama lantai rumah terluas? | W1: 10.b. Bagaimana kondisi lantai tersebut? | X1: 11.a. Apa bahan bangunan utama dinding rumah terluas? | Y1: 11.b. Bagaimana kondisi dinding tersebut? | Z1: 12.a. Apa bahan bangunan utama atap rumah terluas? | AA1: 12.b. Bagaimana kondisi atap tersebut? | AB1: 13. Apakah memiliki fasilitas tempat buang air besar, dan siapa saja yang menggunakan? | AC1: 14. Apakah jenis kloset yang digunakan? | AD1: 15. Dimana tempat pembuangan akhir tinja | AE1: 16. Apa sumber air utama yang digunakan keluarga untuk minum? | AF1: 17. Apakah sumber utama penerangan keluarga ini? | AG1: 18.a. Berapa jumlah meteran listrik yang terpasang di rumah ini? | AH1: 18.b.1. Daya yang terpasang pada meteran ke-1? | AI1: 18.b.2. Daya yang terpasang pada meteran ke-2? | AJ1: 18.b.3. Daya yang terpasang pada meteran ke-3? | AK1: 18.b.4. Daya yang terpasang pada meteran ke-4? | AL1: 19. Berapa nilai pengeluaran listrik sebulan? | AM1: 20. Berapa pengeluaran pulsa dan internet seluruh anggota keluarga sebulan? | AN1: 21. a. Foto tampak depan | AO1: 21.b. Foto ruang tamu | AP1: 21.c. Foto kamar mandi | AQ1: 22.a. Tabung gas 3 kg: | AR1: 22.b. Tabung gas 5,5 kg atau lebih: | AS1: 22.c. Lemari es/kulkas: | AT1: 22.d. AC: | AU1: 22.e. Emas/perhiasan: | AV1: 22.f. Komputer/laptop/tablet: | AW1: 22.g. Sepeda: | AX1: 22.h. Sepeda Listrik: | AY1: 22.i. Sepeda motor (jumlah unit): | AZ1: 22.i. Nilai aset sepeda motor (rupiah): | BA1: 22.j. Mobil (jumlah unit): | BB1: 22.j. Nilai aset mobil (rupiah): | BC1: 23.a. Jumlah lahan lain (selain yang ditempati): | BD1: 23.a. Total nilai harga jual lahan di tempat lain(selain yang ditempati): | BE1: 23.b. Jumlah rumah/bangunan di tempat lain (selain yang ditempati): | BF1: 23.b. Total nilai harga jual rumah/bangunan di tempat lain (selain yang ditempati): | BG1: Daftar Anggota Keluarga | BH1: Petugas | BI1: Errors | BJ1: Url | BK1: Network ID
A2: 309290ac-eb18-42f8-b1ec-7ad01889f7da | B2: Tue May 12 2026 09:29:00 GMT+0700 (Western Indonesia Time) | C2: Mon May 11 2026 10:21:00 GMT+0700 (Western Indonesia Time) | D2: finished | E2: Ending | F2: 105 | G2: 2026-05-11 | H2: WAHYUNI DWI SUSANTI | I2: Agus Sidik Haryono | J2: 3515032501097221 | K2: https://prod-fillout-oregon-s3.s3.us-west-2.amazonaws.com/orgid-431168/flowpublicid-kdFWQQWTckus/fbcf3180-3ccd-4103-9260-2a85d4907a69-l9kkn1OKqWDHpcrwpkNgpzMFUoXG7PzoEYq3L4rJuNYwrdUU3jEkrDnvhna1jOWKN48YbA2Stf2VliFBUv71Aqv1kdAQQIoPfsh/Screenshot_20260511_103503_CamScanner.jpg | L2: Agus Sidik Haryono | M2: Waung | N2: RT 005 RW 003 | O2: 1 | Q2: 3 | R2: 1 | S2: 1 | U2: 120 | V2: 2 | W2: 1 | X2: 1 | Y2: 1 | Z2: 2 | AA2: 1 | AB2: 1 | AC2: 1 | AD2: 1 | AE2: 7 | AF2: 1 | AG2: 1 | AH2: 2 | AL2: 300 | AM2: 260 | AN2: https://prod-fillout-oregon-s3.s3.us-west-2.amazonaws.com/orgid-431168/flowpublicid-kdFWQQWTckus/60506c94-d4c1-4637-8d00-ccae91ef02ca-5U8nsgeoeaSOoW60DaSKiRExhIbVd2od9WII6wy0j2CgKMW8U6Aa9PiOsJLPo2B5KNwcAEq4RLg17yKfYduFBH5um79KD37UB9R/1001028717.jpg | AO2: https://prod-fillout-oregon-s3.s3.us-west-2.amazonaws.com/orgid-431168/flowpublicid-kdFWQQWTckus/0dc04d2b-dcb7-4131-abdc-51f41998e44e-xrCyjw0Mqb0qJta3NDTZsqkSRG31ubHhMB8Z9CoQfKaDLmjtfFMUFsTAZ95sqEGJ5lPkuCchqsGCaotCCpPixCN2yUZhQWpSe3c/1001028718.jpg | AP2: https://prod-fillout-oregon-s3.s3.us-west-2.amazonaws.com/orgid-431168/flowpublicid-kdFWQQWTckus/ba13d00d-a355-4d48-96d9-22de9cddb055-rftYmOJqWQAALzRZcZUhfV3oMkmy4VVhERlzb7PnGXEwPbuS7x5GaDIylGFimp8dQSDdaQrF0aBOgai86g0hYfEZgPTErPcYDTy/1000659110.jpg | AQ2: 2 | AR2: 0 | AS2: 1 | AT2: 1 | AU2: 35 | AV2: 2 | AW2: 1 | AX2: 0 | AY2: 3 | AZ2: 50000000 | BA2: 0 | BC2: 1 | BD2: 118000000 | BE2: 0 | BG2: Agus Sidik Haryono, Wahyuni Dwi Susanti, Aidah Shafira Prameswari Ramadhani | BH2: WAHYUNI DWI SUSANTI | BI2: None | BJ2: https://build.fillout.com/editor/kdFWQQWTckus/results?sessionId=309290ac-eb18-42f8-b1ec-7ad01889f7da | BK2: 61b9663efa370e4b56167c9100933d80
A3: 22c643b1-424d-47ef-9e8e-a16ab270271f | B3: Tue May 12 2026 11:18:00 GMT+0700 (Western Indonesia Time) | C3: Tue May 12 2026 10:54:00 GMT+0700 (Western Indonesia Time) | D3: finished | E3: Ending | F3: 110 | G3: 2026-05-12 | H3: NURUL AKHADIAH | I3: Daryono | J3: 3515031001093587 | K3: https://prod-fillout-oregon-s3.s3.us-west-2.amazonaws.com/orgid-431168/flowpublicid-kdFWQQWTckus/1dc8d6a3-e982-48ca-bdbe-2fd1aef7a5b0-ShE259Pzkor3TwkVuZiUIMvaJDBJd5210tGEOqbwAGdeXjIuwNxaUZUYD6DOzmLUieTkugqOnL7YxbEe0YsoUxFLGtTQKVtpAFS/17785581013454865813691413064330.jpg | L3: Daryono | M3: Waung | N3: RT 010 RW 005 | O3: 1 | Q3: 1 | R3: 1 | S3: 1 | U3: 105 | V3: 2 | W3: 1 | X3: 1 | Y3: 1 | Z3: 2 | AA3: 1 | AB3: 1 | AC3: 1 | AD3: 1 | AE3: 7 | AF3: 1 | AG3: 1 | AH3: 2 | AL3: 250000 | AM3: 150000 | AN3: https://prod-fillout-oregon-s3.s3.us-west-2.amazonaws.com/orgid-431168/flowpublicid-kdFWQQWTckus/28eaf588-24bc-4524-ac3f-6cd9df7ed58f-Uz7g3ZJw7oxeZxV4ltECDi7dm4wD39ltJpRXcwp8YUNZl3ZBoJzMggyTrZZqV5pVfoY0oY93q1arrvUtj8CyT8teuyAtTU0J0KE/IMG-20260512-WA0006.jpg | AO3: https://prod-fillout-oregon-s3.s3.us-west-2.amazonaws.com/orgid-431168/flowpublicid-kdFWQQWTckus/fa57d75e-8c60-47d2-b0f0-21c7c111c95e-GrRgGQcdeiuBL2SjRspw6XCC7rqFzPCrNSg8OaUGuyYkPJ8fvAk8DsUjnbkjfkrG8WZNAoXnRqwpWCMsnUzEFC3vvDuclx0Vs4L/IMG-20260512-WA0008.jpg | AP3: https://prod-fillout-oregon-s3.s3.us-west-2.amazonaws.com/orgid-431168/flowpublicid-kdFWQQWTckus/542ac3b6-6d2f-482e-a36b-d7bb62e2c1aa-tYOnW4uixIFwL7OHEc7SoUzFtjTCpoKyz2s9g8rmFyNDQ9mE4gKbVPB1Mne9BLmm12KyYLiBpMN46sp8tmXoTSPFDjvm5vr8hOZ/IMG-20260512-WA0009.jpg | AQ3: 2 | AR3: 0 | AS3: 2 | AT3: 1 | AU3: 5 | AV3: 0 | AW3: 1 | AX3: 0 | AY3: 3 | AZ3: 20000000 | BA3: 1 | BB3: 90000000 | BC3: 1 | BD3: 6000000 | BE3: 1 | BF3: 350000000 | BG3: Daryono, Edy suharyati, Andin hanifah | BH3: NURUL AKHADIAH | BI3: None | BJ3: https://build.fillout.com/editor/kdFWQQWTckus/results?sessionId=22c643b1-424d-47ef-9e8e-a16ab270271f | BK3: 1028106c5ab47512ef62b3ecf421cd9b
A4: 67ebbfb1-5b72-4dfb-9747-aa619cb9dd84 | B4: Tue May 12 2026 11:25:00 GMT+0700 (Western Indonesia Time) | C4: Mon May 11 2026 15:45:00 GMT+0700 (Western Indonesia Time) | D4: finished | E4: Ending | F4: 106 | G4: 2026-05-12 | H4: SRI SUTARMI | I4: Prayit | J4: 3515032501097202 | K4: https://prod-fillout-oregon-s3.s3.us-west-2.amazonaws.com/orgid-431168/flowpublicid-kdFWQQWTckus/75917fb9-df1e-40fc-91dd-d640230403fe-YvxL93MI8Tud0MVi35PhebjLpuV4VbaQGhmQTuqHcOIJT7LQm12xziWFuvJIJrgJmtE5lozXuzJTGOqgbLax6kTOBIujOpxh394/IMG-20260303-WA0061.jpg | L4: Sri sutarmi | M4: Waung | N4: RT 006 RW 003 | O4: 1 | Q4: 1 | R4: 1 | S4: 1 | U4: 60 | V4: 2 | W4: 1 | X4: 1 | Y4: 1 | Z4: 2 | AA4: 1 | AB4: 1 | AC4: 1 | AD4: 1 | AE4: 7 | AF4: 1 | AG4: 1 | AH4: 2 | AL4: 160000 | AM4: 200000 | AN4: https://prod-fillout-oregon-s3.s3.us-west-2.amazonaws.com/orgid-431168/flowpublicid-kdFWQQWTckus/2c6d3f92-620f-44b7-9b4a-11b1ff2db043-1FUjktX3W71JZkKvYfbNcpVAmnV0e6TZ30CFlkG0JyMjrWjoWBQhspeXTrnJcXFAP4GoQFXXRNbelsy6mF8jOwMyJ726TYpuH9r/Screenshot_20260511-144052_Gallery.jpg | AO4: https://prod-fillout-oregon-s3.s3.us-west-2.amazonaws.com/orgid-431168/flowpublicid-kdFWQQWTckus/eef78fca-d6a8-47c9-b9e7-1b2301263ff4-uB1zUTTrRccQxjD0AqnyxIDgtqL7LfG2f7P1fTe7Sfikge9AocoAr4co9vKQl68h42N0GKhk8BpudWJTigadvzmlqybkcuj9dXf/Screenshot_20260511-144058_Gallery.jpg | AP4: https://prod-fillout-oregon-s3.s3.us-west-2.amazonaws.com/orgid-431168/flowpublicid-kdFWQQWTckus/333a5b45-4630-4e00-91bb-cf0def8b918e-4v6Q23y1ThwElJQz24NT3jMbYDmMLl3j7sCbwO9rCXfECNJeVmXq08bPR60Y4RJOUi29i0NtK3DXTuVXCsAIbnjlJ60Y7XMiD2D/Screenshot_20260511-144103_Gallery.jpg | AQ4: 2 | AR4: 0 | AS4: 1 | AT4: 0 | AU4: 5 | AV4: 1 | AW4: 1 | AX4: 0 | AY4: 2 | AZ4: 15000000 | BA4: 1 | BB4: 20000000 | BC4: 0 | BE4: 0 | BG4: Prayit, Sri sutarmi, Hanna rizky maulidyah, Tadjudin widyo kunjoro | BH4: SRI SUTARMI | BI4: None | BJ4: https://build.fillout.com/editor/kdFWQQWTckus/results?sessionId=67ebbfb1-5b72-4dfb-9747-aa619cb9dd84 | BK4: d93bf55e76226109d2e67b42efed5d04
A5: 3c794c0d-e62b-4535-b0c8-3832f8a8da6c | B5: Tue May 12 2026 12:03:00 GMT+0700 (Western Indonesia Time) | C5: Mon May 11 2026 10:18:00 GMT+0700 (Western Indonesia Time) | D5: finished | E5: Ending | F5: 103 | G5: 2026-05-11 | H5: RINI WIJAYA | I5: Harry Sulistiawan | J5: 3515032203100001 | K5: https://prod-fillout-oregon-s3.s3.us-west-2.amazonaws.com/orgid-431168/flowpublicid-kdFWQQWTckus/90f4560a-c7c8-4945-8f9e-f77eb110f4a3-sbdH6chIqGj7eDpl345PA256ZeUr2hhYqoPpsw0nHReZDwuzFRRbmWnXDJxliwKp7e5htx8kPj82o8SMqZYEBwENu2z8OdHDNO6/1710a355-42fd-4c47-a4b1-aba450f59315.jpg | L5: Harry Sulistiawan | M5: Waung | N5: RT 003 RW 002 | O5: 1 | Q5: 1 | R5: 1 | S5: 1 | U5: 100 | V5: 2 | W5: 1 | X5: 1 | Y5: 1 | Z5: 1 | AA5: 1 | AB5: 1 | AC5: 1 | AD5: 1 | AE5: 2 | AF5: 1 | AG5: 1 | AH5: 2 | AL5: 400 | AM5: 100 | AN5: https://prod-fillout-oregon-s3.s3.us-west-2.amazonaws.com/orgid-431168/flowpublicid-kdFWQQWTckus/696fd6f8-3be0-4d4f-890e-275d484c278c-wVVE215nqbbtZB3k3MG3aRdNl0W3kNF1dHa78UStMQ59kJobPXV4hpkv9H0uNM3UzRyQc45VgHol749d5caXSkLZZs9ZhFcALL8/36baeec2-4e84-4571-b0c9-362ba2f9b62b.jpg | AO5: https://prod-fillout-oregon-s3.s3.us-west-2.amazonaws.com/orgid-431168/flowpublicid-kdFWQQWTckus/1e6f9e25-79c6-491e-9dc1-21bb03c7a007-JxcbSsQ5aH0B4JKoi1owdLZPmAbQPBkkeIr6FQD03GcIPlCvMDXCwGjExf8Sx5sIIGKQFoTa6HvPWsi3v8STlSO7dY1RhYRrKWn/7a99c306-9209-4847-a448-2aaeb98a726e.jpg | AP5: https://prod-fillout-oregon-s3.s3.us-west-2.amazonaws.com/orgid-431168/flowpublicid-kdFWQQWTckus/abe90ebb-4519-4ed3-8c80-ba495697ff90-NYbWnCmv3AFKmYYMe32HEibV3FdyaY9CutPqC10vpA0PoOCO2rJRfUJfPXGCLwTcstVWlD3ow8robMTd5wrITZ1ktXCL4Con6oN/6329982d-8adc-4c9f-8c4b-2d7d0ee305a9.jpg | AQ5: 4 | AR5: 3 | AS5: 1 | AT5: 0 | AU5: 1 | AV5: 0 | AW5: 0 | AX5: 0 | AY5: 3 | AZ5: 10 | BA5: 1 | BB5: 50 | BC5: 0 | BE5: 0 | BG5: Rini wijaya , Melati mutia harin, Elvina Carrisa Harin, Harry Sulistiawan | BH5: RINI WIJAYA | BI5: None | BJ5: https://build.fillout.com/editor/kdFWQQWTckus/results?sessionId=3c794c0d-e62b-4535-b0c8-3832f8a8da6c | BK5: d93bf55e76226109d2e67b42efed5d04
A6: 8bc6f396-7321-49c9-b399-172a13b51254 | B6: Tue May 12 2026 12:09:00 GMT+0700 (Western Indonesia Time) | C6: Tue May 12 2026 10:13:00 GMT+0700 (Western Indonesia Time) | D6: finished | E6: Ending | F6: 105 | G6: 2026-05-12 | H6: WAHYUNI DWI SUSANTI | I6: Sukartin | J6: 3515032504240007 | K6: https://prod-fillout-oregon-s3.s3.us-west-2.amazonaws.com/orgid-431168/flowpublicid-kdFWQQWTckus/29c4fa1a-b3ca-4f2c-abd5-dc1670da4614-CRYTzWfRuPJDy2xANbMcLE5CqAQmoain4FavwhGGDdxE4pMpW06jRpNKVY37aJx4LLggCaeqhxDhtAbi0ukTc8dwwl76ZNvOdks/Screenshot_20260512_080419_WPS-Office.jpg | L6: Sukartin | M6: Waung | N6: RT 005 RW 003 | O6: 1 | Q6: 1 | R6: 1 | S6: 1 | U6: 110 | V6: 2 | W6: 1 | X6: 1 | Y6: 1 | Z6: 2 | AA6: 1 | AB6: 1 | AC6: 1 | AD6: 1 | AE6: 7 | AF6: 1 | AG6: 1 | AH6: 2 | AL6: 150000 | AM6: 0 | AN6: https://prod-fillout-oregon-s3.s3.us-west-2.amazonaws.com/orgid-431168/flowpublicid-kdFWQQWTckus/2d633fce-f37a-4504-9807-f490387dbec7-a2lXcVfmEFtncWsB87x0Xbtnmzv7TMFW91DfBgmEnJ5NS6JounVXQy5YiEQ9zS0wR1RxmV1TiSd8zFIRJM3CL8mnhi3IR6O3Gpp/1001029957.jpg | AO6: https://prod-fillout-oregon-s3.s3.us-west-2.amazonaws.com/orgid-431168/flowpublicid-kdFWQQWTckus/fdecadc3-d0d3-4330-a4a1-91cfb6e02065-vv8A7tfSHBOGMRUP2h2KtA48Y0HN3jYdDS6QrHLatsWPrCrr6w3TnVGqx9rzPsU0w5NTEIaA0gVsJWrp0Rhu5vHJ5AJVfYX2bQ9/1001030012.jpg | AP6: https://prod-fillout-oregon-s3.s3.us-west-2.amazonaws.com/orgid-431168/flowpublicid-kdFWQQWTckus/bc55be35-8038-40f4-a459-db0b17865db5-XJeLkNG1jXeun5FZcadKklWsuKscHcBnvfHzbkAkTpbtN7BTDp9yo8DmDa7gYostigeJeQ5w4wTsnMDX6JJdIVo4Ko6CDz4hSBv/1001030125.jpg | AQ6: 2 | AR6: 0 | AS6: 1 | AT6: 0 | AU6: 6 | AV6: 0 | AW6: 1 | AX6: 0 | AY6: 0 | BA6: 0 | BC6: 0 | BE6: 0 | BG6: Sukartin | BH6: WAHYUNI DWI SUSANTI | BI6: None | BJ6: https://build.fillout.com/editor/kdFWQQWTckus/results?sessionId=8bc6f396-7321-49c9-b399-172a13b51254 | BK6: e2e09caa8dce38633385a5c792cea6ab
A7: b780e335-8449-4a82-8d16-7cb21088a652 | B7: Tue May 12 2026 12:30:00 GMT+0700 (Western Indonesia Time) | C7: Tue May 12 2026 11:54:00 GMT+0700 (Western Indonesia Time) | D7: finished | E7: Ending | F7: 106 | G7: 2026-05-12 | H7: SRI SUTARMI | I7: Hadi santoso | J7: 3515030511140002 | K7: https://prod-fillout-oregon-s3.s3.us-west-2.amazonaws.com/orgid-431168/flowpublicid-kdFWQQWTckus/a5c544d6-b0db-41b8-b3c2-fd35517e2c68-yHcZjI2rrySK0aG1pFDZfBNIRNI2uMaAWFrYKMXEWd02I5s6wJqzdvITNc2XW1C3O8wQ1ZClg427o2cpBhLwBLN29g5ngdxxETx/Screenshot_20260512-114920_Gallery.jpg | L7: Lailil ma'rufah | M7: Waung | N7: RT 006 RW 003 | O7: 1 | Q7: 2 | R7: 1 | S7: 1 | U7: 75 | V7: 2 | W7: 1 | X7: 1 | Y7: 1 | Z7: 2 | AA7: 1 | AB7: 1 | AC7: 1 | AD7: 1 | AE7: 7 | AF7: 1 | AG7: 1 | AH7: 2 | AL7: 350000 | AM7: 300000 | AN7: https://prod-fillout-oregon-s3.s3.us-west-2.amazonaws.com/orgid-431168/flowpublicid-kdFWQQWTckus/1e20b4dc-6265-492f-b32a-ade17f0b4d60-2Jngqykfx4zCqyusvnxYdfHeZzGFPPlB8o6mCSIKc4sOY6hGHB9P0PsOESpgBvZJGbmXIiAlcqtVwvV9BTiUHaeZDVYR3ymPWsk/Screenshot_20260512-115044_Gallery.jpg | AO7: https://prod-fillout-oregon-s3.s3.us-west-2.amazonaws.com/orgid-431168/flowpublicid-kdFWQQWTckus/522927bb-0003-4cb6-8a42-d95ac5118b35-jO93GGN5R6nULKjJna1oFt0vOcL3r73bmR6iY12U9aSdwpKpDzy7PDKc5M9XSPIZTIon4CGUxHctmej82ME7srbgB7246gfK3sH/Screenshot_20260512-114934_Gallery.jpg | AP7: https://prod-fillout-oregon-s3.s3.us-west-2.amazonaws.com/orgid-431168/flowpublicid-kdFWQQWTckus/b734096f-af2f-4d11-9f5b-ceb77a77d584-gDFzaNDDlTbANzM163d5pGl9FfcWvGY4cdISpfKvEBeiPgchTEgVwWz5VaJMB5MshnVJyth2KFteQRKMjsEKKlkk5kZjvJRgcTq/Screenshot_20260512-114951_Gallery.jpg | AQ7: 2 | AR7: 0 | AS7: 1 | AT7: 0 | AU7: 5 | AV7: 2 | AW7: 4 | AX7: 0 | AY7: 2 | AZ7: 25000000 | BA7: 1 | BB7: 200000000 | BC7: 0 | BE7: 0 | BG7: Hadi santoso, Lailil ma"rufah, Alkalifi Dzakwan Hadi, Pradipta rizkie hadi | BH7: SRI SUTARMI | BI7: None | BJ7: https://build.fillout.com/editor/kdFWQQWTckus/results?sessionId=b780e335-8449-4a82-8d16-7cb21088a652 | BK7: d93bf55e76226109d2e67b42efed5d04
A8: 2dcbc864-50e8-4317-97ff-3bfa925cfee1 | B8: Tue May 12 2026 12:57:00 GMT+0700 (Western Indonesia Time) | C8: Tue May 12 2026 09:40:00 GMT+0700 (Western Indonesia Time) | D8: finished | E8: Ending | F8: 107 | G8: 2026-05-12 | H8: SRI WINARTI | I8: Misdi Fradman | J8: 3515061306760004 | K8: https://prod-fillout-oregon-s3.s3.us-west-2.amazonaws.com/orgid-431168/flowpublicid-kdFWQQWTckus/e55568f5-20c6-4327-92e6-174da2c05158-GcZ9Pv8dXXz7OfGnMXrOjFvB5SbOVzbf23Q4rlC3K7g1CKxpjWU9NZvHWfY8Ujo5LQfRQXNv0xXFZxTvfHupRI1Ole0qmSND3q8/IMG-20260512-WA0050.jpg | L8: Kariani | M8: Waung | N8: RT 007 RW 004 | O8: 1 | Q8: 1 | R8: 1 | S8: 1 | U8: 80 | V8: 2 | W8: 1 | X8: 1 | Y8: 1 | Z8: 2 | AA8: 2 | AB8: 1 | AC8: 1 | AD8: 1 | AE8: 7 | AF8: 1 | AG8: 1 | AH8: 1 | AL8: 100 | AM8: 130 | AN8: https://prod-fillout-oregon-s3.s3.us-west-2.amazonaws.com/orgid-431168/flowpublicid-kdFWQQWTckus/c8c05774-ba7f-40a1-9d8e-ef80d80b9dc8-Os8QWJowc4HwXy6WAORaZNvdz0PGTo3qmfA7wJKlNzTiyiLjuJcwuZxMjWGTbMz9DgwIaF7rbl60jy3aGgM1CCHDaa06romBLNq/1000421731.jpg | AO8: https://prod-fillout-oregon-s3.s3.us-west-2.amazonaws.com/orgid-431168/flowpublicid-kdFWQQWTckus/d4002146-882d-42b0-8724-3a11faca76e2-U6G8lBdfkp7CNKBthKHCPKUUa4SMK3JDzCb90Et5QVyqbDqVgkB5ZzrvJ0Vikn5rjpk8o07ENNVIEalNoKBomz9a0yD3j3oTgeJ/1000421766.jpg | AP8: https://prod-fillout-oregon-s3.s3.us-west-2.amazonaws.com/orgid-431168/flowpublicid-kdFWQQWTckus/c3bda370-2a99-48cd-a918-6101b8ff47e5-18jcpPUUeNwytjKROqaZwtv18kM3SgqYT7kqfD7IwkGn9TD2oac89ZrzWggvINAc47SaqhJIdws4MSGrUjeGA1dC5BBQl1rUvST/1000421771.jpg | AQ8: 3 | AR8: 0 | AS8: 1 | AT8: 0 | AU8: 500 | AV8: 0 | AW8: 1 | AX8: 0 | AY8: 3 | AZ8: 18000000 | BA8: 0 | BC8: 0 | BE8: 0 | BG8: Misdi Fradman, Kariani, Akhmat Putra Dedi Setiawan | BH8: SRI WINARTI | BI8: None | BJ8: https://build.fillout.com/editor/kdFWQQWTckus/results?sessionId=2dcbc864-50e8-4317-97ff-3bfa925cfee1 | BK8: 2ed216414a105846b4520f43e8c94ae1
A9: a2410a34-468f-4982-ae3c-246d1b52c7b4 | B9: Tue May 12 2026 13:02:00 GMT+0700 (Western Indonesia Time) | C9: Tue May 12 2026 12:10:00 GMT+0700 (Western Indonesia Time) | D9: finished | E9: Ending | F9: 105 | G9: 2026-05-12 | H9: WAHYUNI DWI SUSANTI | I9: Jonianto | J9: 3515032501097260 | K9: https://prod-fillout-oregon-s3.s3.us-west-2.amazonaws.com/orgid-431168/flowpublicid-kdFWQQWTckus/ecb5d3d9-1417-4afb-a0b7-23649396bd4f-AGXzYA5KNhYfjDXJUEIvtTyf4OFzUzEwVrYhtz5eVBaLdw8jK3t8oKRElVYUdhv6BQRkDPHDecpd3JPpyfvAecLacWn71X3q00H/Screenshot_20260512_122045_CamScanner.jpg | L9: Dian Mita Midariyanti | M9: Waung | N9: RT 005 RW 003 | O9: 1 | Q9: 4 | R9: 1 | S9: 1 | U9: 120 | V9: 2 | W9: 1 | X9: 1 | Y9: 1 | Z9: 2 | AA9: 1 | AB9: 1 | AC9: 1 | AD9: 1 | AE9: 7 | AF9: 1 | AG9: 1 | AH9: 2 | AL9: 250 | AM9: 300 | AN9: https://prod-fillout-oregon-s3.s3.us-west-2.amazonaws.com/orgid-431168/flowpublicid-kdFWQQWTckus/60c9569f-f3a6-4d02-8712-dce566086dd3-90ERRGbl9xtV4H1KoEGOil2HxUcMIUuMIxAHq3YFBjh4WKHukyGSdcEPdFylVM8QuroC9HiTKAUSEArAdjBxzWSaHGt2IaI4uYa/1001030251.jpg | AO9: https://prod-fillout-oregon-s3.s3.us-west-2.amazonaws.com/orgid-431168/flowpublicid-kdFWQQWTckus/d2f8faf0-6f09-4701-ad25-356f95bb067b-saXmzBExD97toeUdSDFbT6E5ZKEwKYkt8JCTTgohi0CNlXJOJ4QNE04BB4Gx0reyysqM0wpF9ru5gqMtwbSHyQDpzyZHjsah6xL/1001030252.jpg | AP9: https://prod-fillout-oregon-s3.s3.us-west-2.amazonaws.com/orgid-431168/flowpublicid-kdFWQQWTckus/77870da9-57eb-478e-9ad1-f6c4ceb26bef-hIAVuehXR6nrFxjeIO4sstCLO3qjNF5cJ6urr8Afj4E5Vq8B6hwPvfRbfMRCsTlnYIahvisGuFfkI1K1YjUNrZqmjSEwAbdj0zv/1001030255.jpg | AQ9: 3 | AR9: 0 | AS9: 1 | AT9: 0 | AU9: 3 | AV9: 0 | AW9: 1 | AX9: 1 | AY9: 3 | AZ9: 35000000 | BA9: 0 | BC9: 0 | BE9: 0 | BG9: Jonianto, Dian Mita Midariyanti, Sandy Pratama Febrianto, Noval Ibnu Hafids | BH9: WAHYUNI DWI SUSANTI | BI9: None | BJ9: https://build.fillout.com/editor/kdFWQQWTckus/results?sessionId=a2410a34-468f-4982-ae3c-246d1b52c7b4 | BK9: e2e09caa8dce38633385a5c792cea6ab
A10: a1a42507-5a1b-454d-b792-d078fec97818 | B10: Tue May 12 2026 13:11:00 GMT+0700 (Western Indonesia Time) | C10: Tue May 12 2026 12:33:00 GMT+0700 (Western Indonesia Time) | D10: finished | E10: Ending | F10: 106 | G10: 2026-05-12 | H10: SRI SUTARMI | I10: Sutiani | J10: 3515030702220007 | K10: https://prod-fillout-oregon-s3.s3.us-west-2.amazonaws.com/orgid-431168/flowpublicid-kdFWQQWTckus/745280cb-cfbe-4bf8-b611-2a40107fc5c5-y9BFWL5IKyJBIt6ZxnqikQOdOtkhKyscKj66pRPg7Vt2E35zhzzYI7aSYZARsCTr0g3yFuxJJqNyZTaMijYBzstxyjoE44XYHc6/Screenshot_20260512-114755_Gallery.jpg | L10: Lailil ma'rufah | M10: Waung | N10: RT 006 RW 003 | O10: 1 | Q10: 2 | R10: Ikut anak | U10: 5 | V10: 2 | W10: 1 | X10: 1 | Y10: 1 | Z10: 2 | AA10: 1 | AB10: 1 | AC10: 1 | AD10: 1 | AE10: 7 | AF10: 1 | AG10: 1 | AH10: 2 | AL10: 0 | AM10: 0 | AN10: https://prod-fillout-oregon-s3.s3.us-west-2.amazonaws.com/orgid-431168/flowpublicid-kdFWQQWTckus/b4d02a4f-07b5-4870-aa75-65f69719a576-6UGboCSMXARL5U8NGFC5BTmlhHhk4p9pedIYxPv7g82lR5okWanazpcHCM7V9gxdkTSNfHhGpqt22TwJR3EoMEz93ZLgZ336ECB/Screenshot_20260512-115044_Gallery.jpg | AO10: https://prod-fillout-oregon-s3.s3.us-west-2.amazonaws.com/orgid-431168/flowpublicid-kdFWQQWTckus/7b28ad10-f67f-4fb4-b96a-6cbb2421c8ce-g5vDQEWKYsaTQkTzsmjOZuC3PiSTKWXy0dLfWGHXd2KoGv6gDIlerzVnCwfXvEk72OgtAQwSWqTzoJ2i4uSUwGzTEEfxg1KaFlt/Screenshot_20260512-114934_Gallery.jpg | AP10: https://prod-fillout-oregon-s3.s3.us-west-2.amazonaws.com/orgid-431168/flowpublicid-kdFWQQWTckus/2544f813-b702-43b2-b225-f5e948bd846b-EjLKNHwJAcm1wqqdlaMi0yjgXkUQKTJKHMKLQd94SrpX13hni4ejQBb5IpSD3XNSqVmnPMRWxmbRyjr9VGxspv6sZjMDvRJPAcf/Screenshot_20260512-114951_Gallery.jpg | AQ10: 0 | AR10: 0 | AS10: 0 | AT10: 0 | AU10: 2 | AV10: 0 | AW10: 0 | AX10: 0 | AY10: 0 | BA10: 0 | BC10: 2000 | BD10: 120000000 | BE10: 0 | BG10: Sutiani | BH10: SRI SUTARMI | BI10: None | BJ10: https://build.fillout.com/editor/kdFWQQWTckus/results?sessionId=a1a42507-5a1b-454d-b792-d078fec97818 | BK10: d93bf55e76226109d2e67b42efed5d04
A11: 6566585d-8eb1-460c-be94-4d4c66c435fc | B11: Tue May 12 2026 16:58:00 GMT+0700 (Western Indonesia Time) | C11: Tue May 12 2026 16:25:00 GMT+0700 (Western Indonesia Time) | D11: finished | E11: Ending | F11: 106 | G11: 2026-05-12 | H11: SRI SUTARMI | I11: Mohammad yasir | J11: 3515031602110001 | K11: https://prod-fillout-oregon-s3.s3.us-west-2.amazonaws.com/orgid-431168/flowpublicid-kdFWQQWTckus/89bb91ef-795c-47cf-b41d-693738f21226-DioHafDaplhl0aaULq09eYeySXR9INQ6STsSUhbyH1L8HY3JaAbSV2fQHxU7SUKVWGDTPCVrdXjyy4UwTFiWR3gffxjBzAmls2d/Screenshot_20260512-162356_WhatsApp.jpg | L11: Fitriyah | M11: Waung | N11: RT 006 RW 003 | O11: 1 | Q11: 1 | R11: Ikut orang tua | U11: 60 | V11: 2 | W11: 1 | X11: 1 | Y11: 1 | Z11: 2 | AA11: 1 | AB11: 1 | AC11: 1 | AD11: 1 | AE11: 2 | AF11: 1 | AG11: 1 | AH11: 2 | AL11: 100000 | AM11: 150000 | AN11: https://prod-fillout-oregon-s3.s3.us-west-2.amazonaws.com/orgid-431168/flowpublicid-kdFWQQWTckus/d33d02e6-5c1f-4ca2-bc93-5f5ac4291315-NaJ784y1BFVgLMINUhpXVuaxYN09VaBFa1blb7hL3cyX6EWk3JKImW6e73xGC6z38YWSDlB9WfVXWzAAlpWl8T4Eq28SN04BrdT/Screenshot_20260512-162127_Gallery.jpg | AO11: https://prod-fillout-oregon-s3.s3.us-west-2.amazonaws.com/orgid-431168/flowpublicid-kdFWQQWTckus/26c3113f-0132-45b6-87c1-8a239c7769fc-qWZ2HNaWPIAflM0IfkbKoc1SZFVtLgzijseCEdPCdazAXEHgFPQwMUjqxIE0xYH79IH1nJBnc7hQXDWDwxsc86our4TldOwdeMS/Screenshot_20260512-162121_Gallery.jpg | AP11: https://prod-fillout-oregon-s3.s3.us-west-2.amazonaws.com/orgid-431168/flowpublicid-kdFWQQWTckus/d68b9355-e28a-4853-ae4e-7aa4a6595f82-BRlkUDUQlzXu9JR1f8lqsSdOOGLNEOLTg1hjazTVUkVcyfX2ZSCEYB5Execa3N5gDoLdXwqCQuJdp85DsQCBjRXz1eXXBXPfNbM/Screenshot_20260512-162114_Gallery.jpg | AQ11: 1 | AR11: 0 | AS11: 1 | AT11: 0 | AU11: 10 | AV11: 1 | AW11: 0 | AX11: 0 | AY11: 2 | AZ11: 25000000 | BA11: 1 | BB11: 150000000 | BC11: 1 | BD11: 120000000 | BE11: 0 | BG11: Mohammad yasir, Fitriyah, Rasyadrasendriya | BH11: SRI SUTARMI | BI11: None | BJ11: https://build.fillout.com/editor/kdFWQQWTckus/results?sessionId=6566585d-8eb1-460c-be94-4d4c66c435fc | BK11: 277e7c0f86c622770d27a4448b7a1a7c
A12: 7ec335dc-4ca3-4775-aa54-12c7f9a7b0e4 | B12: Tue May 12 2026 18:06:00 GMT+0700 (Western Indonesia Time) | C12: Tue May 12 2026 16:42:00 GMT+0700 (Western Indonesia Time) | D12: finished | E12: Ending | F12: 101 | G12: 2026-05-12 | H12: NABILAH MUAZAROH MOCHTAR | I12: Dava narta yudha | J12: 3515031311240003 | K12: https://prod-fillout-oregon-s3.s3.us-west-2.amazonaws.com/orgid-431168/flowpublicid-kdFWQQWTckus/62bcffef-19ed-4535-bae4-6fdf43b66258-QUP2qrbVQQTz7F6sjqEhJZOGGZCa1F5Hy8XsoKO4PlIW1nZfTx8qC0QtOmbWry2z9Oya6cKJMkybxLB1rWQt6cp5Wn5pimFTh2s/WA_1778578498653.jpg | L12: Dava narta yudha | M12: Waung utara | N12: RT 001 RW 001 | O12: 1 | Q12: 2 | R12: 3 | U12: 140 | V12: 6 | W12: 1 | X12: 1 | Y12: 1 | Z12: 2 | AA12: 1 | AB12: 1 | AC12: 3 | AD12: 1 | AE12: 1 | AF12: 1 | AG12: 2200 | AH12: 3 | AI12: 3 | AJ12: 3 | AK12: 3 | AL12: 100000 | AM12: 50000 | AN12: https://prod-fillout-oregon-s3.s3.us-west-2.amazonaws.com/orgid-431168/flowpublicid-kdFWQQWTckus/56d7414a-b52b-4109-b7d4-9ca43dcecf53-1zKox9xzWcQQwVvByP3LVsAV7xyF2t4ByfC3NowHI7PQ4zYvJhaeYYfof3i8uQbG8t6YVUXX6zucwKTotxWDL1tSsm8XnyhckrE/WA_1778579433880.jpg | AO12: https://prod-fillout-oregon-s3.s3.us-west-2.amazonaws.com/orgid-431168/flowpublicid-kdFWQQWTckus/c551dc9e-e3ce-4099-a956-4bda82b8f4ab-VAJJHUWPzDAdnbDk9nOMUzVAFOb10iBMFcAzRPQDS43dKgHLApauPNTQI3qV1GIqAdRhqgdqb5336r2BRfZrPlqhbshLlXmRGCP/20260512_165324.jpg | AP12: https://prod-fillout-oregon-s3.s3.us-west-2.amazonaws.com/orgid-431168/flowpublicid-kdFWQQWTckus/b676ca88-1cfc-48e4-93e2-846dac4bc5f7-lF23PkxXYx0evmMdHUT0NXJL0g1XAqWG3yYTxKUuCi257szttMqfYK3cr69rbVeU81CZQblMGRhgwesnahtysixWPN2q2Xj7Y62/20260512_165722.jpg | AQ12: 0 | AR12: 0 | AS12: 0 | AT12: 0 | AU12: 0 | AV12: 0 | AW12: 0 | AX12: 0 | AY12: 1 | AZ12: 22000000 | BA12: 0 | BC12: 0 | BE12: 0 | BG12: Dava narta yudha, Nabilah muazorah mochtar, Keenand ryuga narta | BH12: NABILAH MUAZAROH MOCHTAR | BI12: None | BJ12: https://build.fillout.com/editor/kdFWQQWTckus/results?sessionId=7ec335dc-4ca3-4775-aa54-12c7f9a7b0e4 | BK12: 91d22f4714f303157d11716cb9588443
A13: 85dc3814-50b9-4bd0-b8b4-ec69ca374e27 | B13: Tue May 12 2026 19:33:00 GMT+0700 (Western Indonesia Time) | C13: Tue May 12 2026 19:09:00 GMT+0700 (Western Indonesia Time) | D13: finished | E13: Ending | F13: 108 | G13: 2026-05-12 | H13: PRIYATNO | I13: wakit ragil | J13: 3515031001093496 | K13: https://prod-fillout-oregon-s3.s3.us-west-2.amazonaws.com/orgid-431168/flowpublicid-kdFWQQWTckus/a365cc58-86a8-4edd-be3c-93ad847ffd49-QqEquXlJBZhIBqtKdczpSpaSGNsW8npMyyZY3PzFesftRWKZrYTM9MCRNOVtoYKOHm1OdyHditZxuG6NBxbBtQKnmg4eaSPc2oR/IMG-20260512-WA0000.jpg | L13: wakit ragil | M13: desa waung | N13: RT 008 RW 004 | O13: 1 | Q13: 1 | R13: 1 | S13: 1 | U13: 70 | V13: 2 | W13: 1 | X13: 1 | Y13: 1 | Z13: 2 | AA13: 1 | AB13: 1 | AC13: 1 | AD13: 1 | AE13: 4 | AF13: 1 | AG13: 1 | AH13: 1 | AL13: 30000 | AM13: 100000 | AN13: https://prod-fillout-oregon-s3.s3.us-west-2.amazonaws.com/orgid-431168/flowpublicid-kdFWQQWTckus/0fcf7b8e-44db-4fb1-8b7f-f663ea5a0651-lVpDmnYTQjHa2fnffJv94vZhpc5OQidlvAeN5J7VfSrCA6pGUH82YhXzdG53kz2q8f6lLzIhfDUlU6oBGFb1Y2OW1WtNE2Kl6SX/IMG-20260512-WA0002.jpg | AO13: https://prod-fillout-oregon-s3.s3.us-west-2.amazonaws.com/orgid-431168/flowpublicid-kdFWQQWTckus/ce05323c-3fc5-4c39-b991-310edb5bb017-QOYg0LCJ5BG1iqAcys0JFJUl99dd0hXxYsq00vEkf7Q8OS76fq6APqMHQs5Jm7vOcN6DPm1K1wTKnn3rFPS6QgMDw9UrVT29gQ6/IMG-20260512-WA0003.jpg | AP13: https://prod-fillout-oregon-s3.s3.us-west-2.amazonaws.com/orgid-431168/flowpublicid-kdFWQQWTckus/d5cdc4b9-df21-4af1-bcaf-17f1437eeeb0-3qjKlTxmAKZRI2q0mbMg09p5gsviHHDGZUFeXYH4ecmGwuBMKGoINc8Wr1IIDniC2q9DlPk4autwPAMU7yI28pOYZZRqLIsHS83/WA_1778551570116.jpg | AQ13: 1 | AR13: 0 | AS13: 1 | AT13: 0 | AU13: 2 | AV13: 0 | AW13: 1 | AX13: 0 | AY13: 1 | AZ13: 3000000 | BA13: 0 | BC13: 0 | BE13: 0 | BG13: wakit ragil, supariati, ulum hanifatus solikhah | BH13: PRIYATNO | BI13: None | BJ13: https://build.fillout.com/editor/kdFWQQWTckus/results?sessionId=85dc3814-50b9-4bd0-b8b4-ec69ca374e27 | BK13: a5b1ee32e3c14293846465b974740550
A14: b8562634-cfaf-475a-94bb-721ef9c519a4 | B14: Tue May 12 2026 19:40:00 GMT+0700 (Western Indonesia Time) | C14: Tue May 12 2026 17:57:00 GMT+0700 (Western Indonesia Time) | D14: finished | E14: Ending | F14: 107 | G14: 2026-05-12 | H14: SRI WINARTI | I14: Sudiono | J14: 3515031001093447 | K14: https://prod-fillout-oregon-s3.s3.us-west-2.amazonaws.com/orgid-431168/flowpublicid-kdFWQQWTckus/34ec2833-6eb0-4330-8e9b-1c1328ff050f-iRT6QnyVVtgtW0ZfjkncZe3Y19maV3KMCWP2jQUzBTbMG8e611RF7tJNe7NWozRBlIuzrMEfxq1gKlS8o0UaKq17CrZUTEMvorZ/WA_1778568239411.jpg | L14: Waras Kholip Suningsih | M14: Waung | N14: RT 007 RW 004 | O14: 1 | Q14: 1 | R14: 1 | S14: 1 | U14: 108 | V14: 2 | W14: 1 | X14: 1 | Y14: 1 | Z14: 2 | AA14: 1 | AB14: 1 | AC14: 1 | AD14: 1 | AE14: 7 | AF14: 1 | AG14: 1 | AH14: 2 | AL14: 100 | AM14: 70 | AN14: https://prod-fillout-oregon-s3.s3.us-west-2.amazonaws.com/orgid-431168/flowpublicid-kdFWQQWTckus/4ea51be4-9f5a-42f0-a1d3-0f66c944d175-c0s3yzP08j0tWSoDSrbo5O0YGbSjGJ55gVYEF0ubqJ8w5dybr6Z78F35ErSvGyvkUrSGm4qyNj5OrKjOsdXe8bckhOjLCuIHDuL/1000422105.jpg | AO14: https://prod-fillout-oregon-s3.s3.us-west-2.amazonaws.com/orgid-431168/flowpublicid-kdFWQQWTckus/8a6af1f4-84f8-40e2-bc78-583661e02f4b-rwMy6L1G3eMikwHLt70A643jI4q0W0BAURXNirzGc1PNRplP68ZUWiKb9hMErawqCKNZGpFWthQtjFK8H8PVFNoaSUA6F4qtU0U/1000421857.jpg | AP14: https://prod-fillout-oregon-s3.s3.us-west-2.amazonaws.com/orgid-431168/flowpublicid-kdFWQQWTckus/02a97dcb-dc3c-4f4f-9ce4-876a232c4a2b-bdc3MK69OaDgdm6ZgMgReDEskTB9MV3QxvCWbFXFfHcogE0eqV0kaK8hnvbhJRmoIieHCrhoZC0WmOxyfGYWVY23ZvYdRBUKRBq/1000421859.jpg | AQ14: 2 | AR14: 0 | AS14: 0 | AT14: 0 | AU14: 5 | AV14: 0 | AW14: 1 | AX14: 0 | AY14: 2 | AZ14: 4000000 | BA14: 0 | BC14: 0 | BE14: 0 | BG14: Sudiono, Waras Kholip Suningsih | BH14: SRI WINARTI | BI14: None | BJ14: https://build.fillout.com/editor/kdFWQQWTckus/results?sessionId=b8562634-cfaf-475a-94bb-721ef9c519a4 | BK14: 2ed216414a105846b4520f43e8c94ae1
A15: 6435f591-f7a9-4235-ad37-033ae4decda5 | B15: Tue May 12 2026 20:13:00 GMT+0700 (Western Indonesia Time) | C15: Mon May 11 2026 10:20:00 GMT+0700 (Western Indonesia Time) | D15: finished | E15: Ending | F15: 104 | G15: 2026-05-11 | H15: SITI AISYAH | I15: Ardiyanto | J15: 3515032911110006 | K15: https://prod-fillout-oregon-s3.s3.us-west-2.amazonaws.com/orgid-431168/flowpublicid-kdFWQQWTckus/d63e7752-8be7-4622-8ba1-145b322be99f-U5aocskiP88dF8HLJvwI7VBHlvAplLqlieZYKnPqGwehhX20BG00QIoCDDzVq36aj8CY8F5M2JoTWqgDkrk0TKQV2kXDdXEJPUS/Screenshot_20240617-070503.png | L15: Ardiyanto | M15: Waung | N15: RT 004 RW 002 | O15: 1 | Q15: 1 | R15: 1 | S15: 4 | U15: 60 | V15: 2 | W15: 1 | X15: 1 | Y15: 1 | Z15: 2 | AA15: 1 | AB15: 1 | AC15: 1 | AD15: 1 | AE15: 7 | AF15: 1 | AG15: 1 | AH15: 1 | AL15: 50000 | AM15: 100000 | AN15: https://prod-fillout-oregon-s3.s3.us-west-2.amazonaws.com/orgid-431168/flowpublicid-kdFWQQWTckus/a8e71c26-2511-4229-b01a-64a5a094391a-rC2kpLHMbCFIZU1aOHMe8DMp2o2nHFR2sM5cy055rwGBMu2tTtucCXwcrU68hzBGGchzjudTFUsV5kEWt4SXZC42NGnHQYbWXvV/215531.jpg | AO15: https://prod-fillout-oregon-s3.s3.us-west-2.amazonaws.com/orgid-431168/flowpublicid-kdFWQQWTckus/c1ae9b70-0eeb-4ea9-ae99-6256af8c8e30-zmINuHVj3945EExOA2PeNMZHSMQCkrYlua1GRztazi6dqmHul0WdWgH6dwN33sAjQd25lTZzSnWJG4UVKOuSoY2uIBxwR7VAhKv/215525.jpg | AP15: https://prod-fillout-oregon-s3.s3.us-west-2.amazonaws.com/orgid-431168/flowpublicid-kdFWQQWTckus/f8a72da8-e296-4e4b-9ec3-45fe3ea4f444-vO6j7rTJaox1YDB3VhfQQE2hukrDkZCvNkSUATiR9FQSw4HdKeWHpwxlOCa7kSMETaT4IITFiRtIHll7PvZFEwGxNMwOOFztcAw/215522.jpg | AQ15: 1 | AR15: 0 | AS15: 0 | AT15: 0 | AU15: 0 | AV15: 0 | AW15: 0 | AX15: 0 | AY15: 1 | AZ15: 5000000 | BA15: 0 | BC15: 0 | BE15: 0 | BG15: Ardiyanto, Siti Aisyah, Asrory ubaid hidayatullah | BH15: SITI AISYAH | BI15: None | BJ15: https://build.fillout.com/editor/kdFWQQWTckus/results?sessionId=6435f591-f7a9-4235-ad37-033ae4decda5 | BK15: 87b2be06fe24b23c1179242f77cbe214
A16: 4be0be74-bd0a-4e1e-affa-0e04a479af9e | B16: Tue May 12 2026 20:28:00 GMT+0700 (Western Indonesia Time) | C16: Tue May 12 2026 19:42:00 GMT+0700 (Western Indonesia Time) | D16: finished | E16: Ending | F16: 107 | G16: 2026-05-12 | H16: SRI WINARTI | I16: Bambang Usman | J16: 3515032503130001 | K16: https://prod-fillout-oregon-s3.s3.us-west-2.amazonaws.com/orgid-431168/flowpublicid-kdFWQQWTckus/c9691016-dd46-41fb-91cc-6518382e865a-aeWQfnr1C3klEGTqW19hCZk5wqmAWtHPTZtqf7w8369LunzC72tIewfq6hyIk2nUl6rDrEp5C7eYyJBKzG0LxA53SaA9S9vYPPZ/WA_1778589990574.jpg | L16: Sri Winarti | M16: Waung | N16: RT 007 RW 004 | O16: 1 | Q16: 1 | R16: 3 | U16: 105 | V16: 2 | W16: 1 | X16: 1 | Y16: 1 | Z16: 4 | AA16: 1 | AB16: 1 | AC16: 1 | AD16: 1 | AE16: 2 | AF16: 2 | AL16: 100 | AM16: 70 | AN16: https://prod-fillout-oregon-s3.s3.us-west-2.amazonaws.com/orgid-431168/flowpublicid-kdFWQQWTckus/caaa78e4-3a9c-4d22-9c4b-62e804e10952-OVoCHyKpsAxHIv4vbEc8g1ADgQ5xWWvidehWSWUks8B5QiPJAtmSlBu4WnsgYDyn97PXoz4FHGMXAWXIX93r8kzmAQ4wi25NWjA/1000422349.jpg | AO16: https://prod-fillout-oregon-s3.s3.us-west-2.amazonaws.com/orgid-431168/flowpublicid-kdFWQQWTckus/f3af7471-dbf0-42dd-b248-a97a1188220b-Ic7CBMUz0RIjQIScxKNBcCx1JzaxGEsENqYGpdUfjAf9dwCnzxso0ZztaiEmZhhN38vXNQD0sn22nHcfQnrUIzqFG6BbWJUThbl/1000422352.jpg | AP16: https://prod-fillout-oregon-s3.s3.us-west-2.amazonaws.com/orgid-431168/flowpublicid-kdFWQQWTckus/1b4e69ac-9975-4ca7-b3a5-fda6d8f7b8d6-5tAqVOAKyAeWPGZiFf9YZ6mhdMv0LixyroXi8RGk7GXaLknQO51AX3MAS20Smik3LVaaI9Me9IGkGhHob7Z7LcopzBOz0cvyiun/1000422355.jpg | AQ16: 1 | AR16: 0 | AS16: 1 | AT16: 0 | AU16: 1 | AV16: 0 | AW16: 1 | AX16: 0 | AY16: 2 | AZ16: 11000000 | BA16: 0 | BC16: 1 | BD16: 100000000 | BE16: 0 | BG16: Bambang Usman, Sri Winarti, Salsabila Putri Febriana, Reviana Aulia Azzahra | BH16: SRI WINARTI | BI16: None | BJ16: https://build.fillout.com/editor/kdFWQQWTckus/results?sessionId=4be0be74-bd0a-4e1e-affa-0e04a479af9e | BK16: 2ed216414a105846b4520f43e8c94ae1
A17: ab62dc87-8d72-42eb-9775-813b7d8490a0 | B17: Tue May 12 2026 20:58:00 GMT+0700 (Western Indonesia Time) | C17: Tue May 12 2026 16:28:00 GMT+0700 (Western Indonesia Time) | D17: finished | E17: Ending | F17: 105 | G17: 2026-05-12 | H17: WAHYUNI DWI SUSANTI | I17: Abdul gofur | J17: 3515031012090001 | K17: https://prod-fillout-oregon-s3.s3.us-west-2.amazonaws.com/orgid-431168/flowpublicid-kdFWQQWTckus/cd17f9be-c65a-43c9-bdbe-9c55fd6bcc7d-dY1bvuRsTketMJobSyMkL4A0uFyEOOooCvZW4oVWFTt8aQVkYMvMIrklbTJ0oynquVb4huGuZCrOHchnyhZImyQWwOBsKZNKQrv/Screenshot_20260512_160412_CamScanner.jpg | L17: Suyanti | M17: Waung | N17: RT 005 RW 003 | O17: 1 | Q17: 1 | R17: 1 | S17: 1 | U17: 91 | V17: 2 | W17: 1 | X17: 1 | Y17: 1 | Z17: 2 | AA17: 1 | AB17: 1 | AC17: 1 | AD17: 1 | AE17: 7 | AF17: 1 | AG17: 1 | AH17: 1 | AL17: 50000 | AM17: 0 | AN17: https://prod-fillout-oregon-s3.s3.us-west-2.amazonaws.com/orgid-431168/flowpublicid-kdFWQQWTckus/fc3a9f61-6662-4da4-b193-dc8ff24a7019-wylVxF6xuV1fGqK9OeWZ5T8niTGPHjyfd2o6ogWAY3VMTPktRfmARzffdPkLtlAZfJrLrbs7pmRGCZFacSyqtKMUpieq06HGOk9/1001030277.jpg | AO17: https://prod-fillout-oregon-s3.s3.us-west-2.amazonaws.com/orgid-431168/flowpublicid-kdFWQQWTckus/9d2af800-a6fa-4f41-9d10-14c4f09a6b87-9J03Tu75IGOTfYgLetszkr2P83aUKkcyU7Nb4HbGeRhQa2gKFKzbCwKKNHNAOkvlJiq1uKDBBfh8PXPKVA7ORKdc2V0YOGltbDs/1001030278.jpg | AP17: https://prod-fillout-oregon-s3.s3.us-west-2.amazonaws.com/orgid-431168/flowpublicid-kdFWQQWTckus/4a128a65-6780-498a-868e-1bc1682f8b6e-V1gtohjqKnzZOSh46xkxWDBPk57Wp9sq3F16VHnKeVRoTDeoYcrux7sPIdu3S9dBEX1xIVomJyGiMGw21oAQlmQg7qcaYhTWfhZ/1001030417.jpg | AQ17: 1 | AR17: 0 | AS17: 1 | AT17: 0 | AU17: 0 | AV17: 0 | AW17: 2 | AX17: 0 | AY17: 1 | AZ17: 7000000 | BA17: 0 | BC17: 0 | BE17: 0 | BG17: Abdul Gofur, Suyanti, Ananda Mathasia | BH17: WAHYUNI DWI SUSANTI | BI17: None | BJ17: https://build.fillout.com/editor/kdFWQQWTckus/results?sessionId=ab62dc87-8d72-42eb-9775-813b7d8490a0 | BK17: e2e09caa8dce38633385a5c792cea6ab
A18: 67bc68a6-b2ff-4263-84b9-7fc651207c2a | B18: Tue May 12 2026 21:34:00 GMT+0700 (Western Indonesia Time) | C18: Tue May 12 2026 20:41:00 GMT+0700 (Western Indonesia Time) | D18: finished | E18: Ending | F18: 104 | G18: 2026-05-12 | H18: SITI AISYAH | I18: Kartik | J18: 3515031001093333 | K18: https://prod-fillout-oregon-s3.s3.us-west-2.amazonaws.com/orgid-431168/flowpublicid-kdFWQQWTckus/bde0cd90-f665-4481-b99e-53cf0f067b8c-xiUdHMpzoeAuRpak2QP3Tk1sov0g2xkGwvTxjKszB8jJ1hcuQi4EDOnEukVRTDZ3Ehdz9mX1cnzbfIneLmOMgfsE8DynKhQKPjE/KK-kartik.jpg | L18: Kartik | M18: Waung | N18: RT 004 RW 002 | O18: 1 | Q18: 1 | R18: 1 | S18: 1 | U18: 90 | V18: 2 | W18: 1 | X18: 1 | Y18: 1 | Z18: 2 | AA18: 1 | AB18: 1 | AC18: 1 | AD18: 1 | AE18: 1 | AF18: 1 | AG18: 1 | AH18: 1 | AL18: 70000 | AM18: 50000 | AN18: https://prod-fillout-oregon-s3.s3.us-west-2.amazonaws.com/orgid-431168/flowpublicid-kdFWQQWTckus/074d723a-af9f-4e5b-9f23-63d53cab9e02-FuOf3m8jtQsNSRxJXO2Kh2pIK0F52SnOvcAMY61fbQ9FQlE2K1vd9UyRhsNGmWe7T1COgZJqBdOjWtpP6E8hO6nCLUE8JkbtrlT/215970.jpg | AO18: https://prod-fillout-oregon-s3.s3.us-west-2.amazonaws.com/orgid-431168/flowpublicid-kdFWQQWTckus/ddc3d61a-f61f-4786-b201-30207cb36809-de7eEtaEK2MklkGg6sXwFsINnUExn8vPd7A7CLz1eEtRFtITaV0XpazOrLvWg54VQ3qPFMz7GydFzBOgtPGIZCkgitX0nObuvEP/215971.jpg | AP18: https://prod-fillout-oregon-s3.s3.us-west-2.amazonaws.com/orgid-431168/flowpublicid-kdFWQQWTckus/e0c2cea0-8c9b-48ca-bbdb-c8ef920ec079-NxBfx6FZBvSM3nAShr8KA9KVe6QyWNkfhpEBWewGcAOLvtkc6HOdGIJKjpZEl3Krnl2fTy3Js5O6Z7uoP0vzUYyRyE0IXpAwtG1/215974.jpg | AQ18: 2 | AR18: 0 | AS18: 1 | AT18: 0 | AU18: 3 | AV18: 0 | AW18: 1 | AX18: 0 | AY18: 1 | AZ18: 20000000 | BA18: 0 | BC18: 1 | BD18: 200000000 | BE18: 0 | BG18: Kartik | BH18: SITI AISYAH | BI18: None | BJ18: https://build.fillout.com/editor/kdFWQQWTckus/results?sessionId=67bc68a6-b2ff-4263-84b9-7fc651207c2a | BK18: 87b2be06fe24b23c1179242f77cbe214
A19: 663bbf3c-7373-4a66-9b52-55c49eaec746 | B19: Tue May 12 2026 22:52:00 GMT+0700 (Western Indonesia Time) | C19: Tue May 12 2026 22:13:00 GMT+0700 (Western Indonesia Time) | D19: finished | E19: Ending | F19: 106 | G19: 2026-05-12 | H19: SRI SUTARMI | I19: Suparno | J19: 3515031001093440 | K19: https://prod-fillout-oregon-s3.s3.us-west-2.amazonaws.com/orgid-431168/flowpublicid-kdFWQQWTckus/dc4ebf2e-89a4-4244-84c4-a4b5739ef42a-56cowxOp7j1HPVb1fxWKYtbKhd1Dyn3hE8JYIHm3T44ex6JD3zTJ4DiY7HQwikQgMZSPn9k2lOXo8NC7lR4efDtkmgymW1F5kNA/Screenshot_20260512-162041_Gallery.jpg | L19: Sutilah | M19: Waung | N19: RT 006 RW 003 | O19: 1 | Q19: 2 | R19: 1 | S19: 1 | U19: 60 | V19: 2 | W19: 1 | X19: 1 | Y19: 1 | Z19: 2 | AA19: 1 | AB19: 1 | AC19: 1 | AD19: 1 | AE19: 2 | AF19: 1 | AG19: 1 | AH19: 1 | AL19: 60 | AM19: 200000 | AN19: https://prod-fillout-oregon-s3.s3.us-west-2.amazonaws.com/orgid-431168/flowpublicid-kdFWQQWTckus/488ca76c-82bd-4835-ab64-6d88e8bb8eb9-JnZpaqckWv3zzWXMu9VlBHBUGfLOVXEchHYEX4URi5sq5MJxbW8jEnc2IDC6hl3FMjG8aCFhkvPiQym4deAMAOrv30gAk2NC1sV/Screenshot_20260512-162242_Gallery.jpg | AO19: https://prod-fillout-oregon-s3.s3.us-west-2.amazonaws.com/orgid-431168/flowpublicid-kdFWQQWTckus/3ba18af5-bc6d-4d29-ba9b-58cf369c281e-8qhwIYMRQBHBkhSzGgI6B1sA0l2Ev56kizksnxTukCpnPJKmvWvVBN8ro8MwOOw8IYAM1n92LAAysvHrmZKOGcUW8hnNRyCEK3u/Screenshot_20260512-162056_Gallery.jpg | AP19: https://prod-fillout-oregon-s3.s3.us-west-2.amazonaws.com/orgid-431168/flowpublicid-kdFWQQWTckus/9e7b18f9-c1af-4f18-a9be-0235dc2dc8aa-1yzz6kZQseHfHIep7ABRFk2KBL3ygqrRKrNDLSGCDN4OxFXNs0VjkmoM25oRPK5WPsDNLNkfOvF5y302Lklu4bRkJUFJKY5gCQT/Screenshot_20260512-162108_Gallery.jpg | AQ19: 1 | AR19: 0 | AS19: 1 | AT19: 0 | AU19: 3 | AV19: 0 | AW19: 1 | AX19: 0 | AY19: 2 | AZ19: 15000000 | BA19: 0 | BC19: 0 | BE19: 0 | BG19: Suparno, Sutilah, As'ari, Jilan Nafiah, Afif Muzakki | BH19: SRI SUTARMI | BI19: None | BJ19: https://build.fillout.com/editor/kdFWQQWTckus/results?sessionId=663bbf3c-7373-4a66-9b52-55c49eaec746 | BK19: 91d22f4714f303157d11716cb9588443
A20: f937cc90-3e66-451a-9817-13994cd7125c | B20: Tue May 12 2026 22:57:00 GMT+0700 (Western Indonesia Time) | C20: Tue May 12 2026 21:45:00 GMT+0700 (Western Indonesia Time) | D20: finished | E20: Ending | F20: 104 | G20: 2026-05-12 | H20: SITI AISYAH | I20: Moh.Anwar | J20: 3515032701110003 | K20: https://prod-fillout-oregon-s3.s3.us-west-2.amazonaws.com/orgid-431168/flowpublicid-kdFWQQWTckus/f22e98b3-3682-4b08-84aa-d65298ba8fb2-WJkLvMOtttUGWaAN1YX5ARDWcEocRL20zht4S3mQQfSwU4dpCrFEGFI3Mf6Zghlmgs7wpFPfG4A5nnojgEDnZ4aQuKEtoMiA6DA/IMG-20260512-WA0095.jpg | L20: Moh.Anwar | M20: Waung | N20: RT 004 RW 002 | O20: 1 | Q20: 1 | R20: 1 | S20: 1 | U20: 100 | V20: 6 | W20: 1 | X20: 1 | Y20: 1 | Z20: 2 | AA20: 1 | AB20: 1 | AC20: 1 | AD20: 1 | AE20: 5 | AF20: 1 | AG20: 1 | AH20: 1 | AL20: 60000 | AM20: 25000 | AN20: https://prod-fillout-oregon-s3.s3.us-west-2.amazonaws.com/orgid-431168/flowpublicid-kdFWQQWTckus/20da39e8-ceb1-4edb-83c9-eaded3e59d16-Qqu3871shv2Fwf93gyOcnhnKxqif90SbMAQSDgS7teMu2F3bBnICn6KciFZxjaxSDeY3pVin0Nycm8YJzS6iExVGvxDUcZUGRA5/216034.jpg | AO20: https://prod-fillout-oregon-s3.s3.us-west-2.amazonaws.com/orgid-431168/flowpublicid-kdFWQQWTckus/53e96ebe-1a04-48c0-91df-8aa69c9ff1c7-4uxsHPgB7RV5t8TmmUE996Z13NZ13pXNzkbND6M3vJJeRBoiuDG2N1pqtWNlN1OmukAGvRsTwBdzNrHlx8QiEeMVeo95OUcvh9J/216035.jpg | AP20: https://prod-fillout-oregon-s3.s3.us-west-2.amazonaws.com/orgid-431168/flowpublicid-kdFWQQWTckus/ca394ac7-bac1-4137-bd69-b013298e7a72-ZlkSzdgi4LsnrWGLc2B6ZzEqnmW9D5gr9cvSSn5si5uryngPoderlqtryXTtbBgwBQtKXEoHviaVaDJ34a5pUnHH7LY16DPBLz0/216036.jpg | AQ20: 2 | AR20: 0 | AS20: 1 | AT20: 0 | AU20: 0 | AV20: 0 | AW20: 0 | AX20: 0 | AY20: 1 | AZ20: 1500000 | BA20: 0 | BC20: 0 | BE20: 0 | BG20: Moh.Anwar, Sumarni | BH20: SITI AISYAH | BI20: None | BJ20: https://build.fillout.com/editor/kdFWQQWTckus/results?sessionId=f937cc90-3e66-451a-9817-13994cd7125c | BK20: 87b2be06fe24b23c1179242f77cbe214
A21: d736fc32-c1ba-4952-baf7-ea76d1f5f87e | B21: Tue May 12 2026 23:08:00 GMT+0700 (Western Indonesia Time) | C21: Tue May 12 2026 22:52:00 GMT+0700 (Western Indonesia Time) | D21: finished | E21: Ending | F21: 106 | G21: 2026-05-12 | H21: SRI SUTARMI | I21: Anis nadiroh | J21: 3515032104200001 | K21: https://prod-fillout-oregon-s3.s3.us-west-2.amazonaws.com/orgid-431168/flowpublicid-kdFWQQWTckus/f001af41-08c1-4ff4-84b5-cc8037e84f20-jZkOtEafHaxUnoPkaPsB9YHV6CCncfrZ9qV6wgDRjAXZQB1Bi3pTF2SumO1VvbiYyVRqiq07mYum65Ra6LCYS5N9dCD3PafCXcP/Screenshot_20260512-162048_Gallery.jpg | L21: Sutilah | M21: Waung | N21: RT 006 RW 003 | O21: 1 | Q21: 2 | R21: 1 | S21: 1 | U21: 12 | V21: 2 | W21: 1 | X21: 1 | Y21: 1 | Z21: 2 | AA21: 1 | AB21: 1 | AC21: 1 | AD21: 1 | AE21: 2 | AF21: 1 | AG21: 1 | AH21: 1 | AL21: 15000 | AM21: 50000 | AN21: https://prod-fillout-oregon-s3.s3.us-west-2.amazonaws.com/orgid-431168/flowpublicid-kdFWQQWTckus/deb095aa-c4b7-4a44-a42b-316be99e3cd9-M9nofXitPpSv2bJsT80O5PQAHzVzdGeQOUy3Uj0DIsKGJExcqeFdBJ6FTGqiaMCACkO0dN4Lkvoqdm1CajVa2Ia7FwQp3xmuOcF/Screenshot_20260512-162242_Gallery.jpg | AO21: https://prod-fillout-oregon-s3.s3.us-west-2.amazonaws.com/orgid-431168/flowpublicid-kdFWQQWTckus/fd050e8d-3f6d-44cb-a0fe-d8d30393d116-7ujYvqD421GRY9rr0BsxGd4vNvTehenEqfQEeS4YtP04dZybrLtpFQAwpzqNPIu5HQbPD9BtfDfWiKDM1FMRKBQNhnOXSL1N2Cs/Screenshot_20260512-162056_Gallery.jpg | AP21: https://prod-fillout-oregon-s3.s3.us-west-2.amazonaws.com/orgid-431168/flowpublicid-kdFWQQWTckus/ccdce5d8-7e3e-4a27-b99b-349ba49bfd2b-DLQs5VDD44ODGSww6T6WJTDB2jjyHQLnjHK3FjqQRClopBGefLHFmabKpcoYjKKGJp1g55HPm9Dkx0RBDiB7PqT4zu4o55ay600/Screenshot_20260512-162108_Gallery.jpg | AQ21: 0 | AR21: 0 | AS21: 0 | AT21: 0 | AU21: 4 | AV21: 0 | AW21: 1 | AX21: 0 | AY21: 1 | AZ21: 9000000 | BA21: 0 | BC21: 0 | BE21: 0 | BG21: Anis nadiroh, Rifky najwan widjaya | BH21: SRI SUTARMI | BI21: None | BJ21: https://build.fillout.com/editor/kdFWQQWTckus/results?sessionId=d736fc32-c1ba-4952-baf7-ea76d1f5f87e | BK21: 91d22f4714f303157d11716cb9588443
A22: a986ade3-5241-4e57-bce0-a8d0389a0f90 | B22: Tue May 12 2026 23:08:00 GMT+0700 (Western Indonesia Time) | C22: Tue May 12 2026 22:40:00 GMT+0700 (Western Indonesia Time) | D22: finished | E22: Ending | F22: 108 | G22: 2026-05-12 | H22: PRIYATNO | I22: Muhammad sofa | J22: 3515031001093492 | K22: https://prod-fillout-oregon-s3.s3.us-west-2.amazonaws.com/orgid-431168/flowpublicid-kdFWQQWTckus/a617e188-6c7d-4316-8bcd-a9576f6af32c-Ccl39KbfG9cqZZTzrHiMIVgostRtgZNUGsZX7DthVtiysPhaOyHYitQD5dg68gacTLez2GVI0HW3IB9EATsYFZvYZt0ozBRTPpd/WA_1778600536086.jpg | L22: Muhammad sofa | M22: desa waung | N22: RT 008 RW 004 | O22: 1 | Q22: 1 | R22: 1 | S22: 1 | U22: 60 | V22: 2 | W22: 1 | X22: 1 | Y22: 2 | Z22: 4 | AA22: 2 | AB22: 1 | AC22: 1 | AD22: 1 | AE22: 4 | AF22: 1 | AG22: 1 | AH22: 1 | AL22: 30000 | AM22: 100000 | AN22: https://prod-fillout-oregon-s3.s3.us-west-2.amazonaws.com/orgid-431168/flowpublicid-kdFWQQWTckus/06d6a2c1-5efc-4763-8464-6bb7382bc7ba-Jf3oe1XPH9l41D40Ys32s5dHq5iydEENuJcnpYn0dovZG6wuNiv3cWZxp1ogKfqjqh2m01TxDyusA3aUULXWqbueRBTcZc5KKVu/WA_1778600228558.jpg | AO22: https://prod-fillout-oregon-s3.s3.us-west-2.amazonaws.com/orgid-431168/flowpublicid-kdFWQQWTckus/cd73f0b5-d023-4463-bd06-ae8c4dbc9adb-fBzSjleeXa6RTuzyWVrfw5JrHbsSvbkp0EB6fdF2yOR5ZxSCq0tBtFZbnEaxuRzRS9KcRorbg6QWCC1KEseDdYWHICm4SJn2LV5/WA_1778600280756.jpg | AP22: https://prod-fillout-oregon-s3.s3.us-west-2.amazonaws.com/orgid-431168/flowpublicid-kdFWQQWTckus/3b0ffc87-c39d-45e4-b597-c32530d7b5eb-qYn2eYkudza0AzThylL9E1etNQeC8eRDDVHW1LazY5ckE5x0DfvjLDVkMotJJjVVHA2jed59B2ATwMv2MxjC8iAagcyJHkdSInB/WA_1778600316861.jpg | AQ22: 1 | AR22: 0 | AS22: 1 | AT22: 0 | AU22: 2 | AV22: 0 | AW22: 1 | AX22: 0 | AY22: 1 | AZ22: 3500000 | BA22: 0 | BC22: 0 | BE22: 0 | BG22: Muhammad sofa, ani fatimah, afdilah rochimi | BH22: PRIYATNO | BI22: None | BJ22: https://build.fillout.com/editor/kdFWQQWTckus/results?sessionId=a986ade3-5241-4e57-bce0-a8d0389a0f90 | BK22: 2ed216414a105846b4520f43e8c94ae1
A23: 369b12fa-a078-4793-9170-6d973e1a24e1 | B23: Wed May 13 2026 08:18:00 GMT+0700 (Western Indonesia Time) | C23: Tue May 12 2026 23:01:00 GMT+0700 (Western Indonesia Time) | D23: finished | E23: Ending | F23: 104 | G23: 2026-05-12 | H23: SITI AISYAH | I23: Sudrikah | J23: 3515031001093352 | K23: https://prod-fillout-oregon-s3.s3.us-west-2.amazonaws.com/orgid-431168/flowpublicid-kdFWQQWTckus/77c0cc00-74e4-4d81-94d2-d0a3d20c19b5-ORG2sPiJzw7gmf3yp4grBIKNrLeZJgC47zecpWYnUvy8tQyaid5ndlAN4kyQXEXl28LfkW8XC8WdbZAIwx9qC27ElIGKvJGHo4I/IMG-20260512-WA0086.jpg | L23: Sudrikah | M23: Waung | N23: RT 004 RW 002 | O23: 1 | Q23: 2 | R23: 1 | S23: 1 | U23: 48 | V23: 1 | W23: 1 | X23: 1 | Y23: 1 | Z23: 2 | AA23: 1 | AB23: 1 | AC23: 1 | AD23: 1 | AE23: 1 | AF23: 1 | AG23: 1 | AH23: 2 | AL23: 300000 | AM23: 100000 | AN23: https://prod-fillout-oregon-s3.s3.us-west-2.amazonaws.com/orgid-431168/flowpublicid-kdFWQQWTckus/96d114c1-86f5-4250-9d90-d4162831d58e-paNgymxi1gNT5YuPhljoOUun4hFM7Asd3AhjMtvJ5BftOS2PrDRgjaNoQ5G8ADFtIBlo4grBHq25dArJ773GbUAOrTQ0T9D3DQR/216014.jpg | AO23: https://prod-fillout-oregon-s3.s3.us-west-2.amazonaws.com/orgid-431168/flowpublicid-kdFWQQWTckus/0d5f17a6-a174-4bc6-9b78-cd11ddf4c9d0-7ZiAvKmsptfbKquUu4tTAljMfYjkeQaEBW8e1HsiD5jqyORMr8TkuwVGbmdDyHpV6cu7sQ6qjpHu0SfoTceKiWOA8nm5CQWEoth/216015.jpg | AP23: https://prod-fillout-oregon-s3.s3.us-west-2.amazonaws.com/orgid-431168/flowpublicid-kdFWQQWTckus/e74cdd9b-f2bc-4e16-8555-2ef8bf047413-wJcWO9FLajLq1oq6V29cllKRUny3nRhrgmBlExMYJ6UpIaqNUhr8A3t6J00dg9fykOCDlHJrtL6YlhPMI5fEqzy0rUrnIdZFyZj/216016.jpg | AQ23: 1 | AR23: 0 | AS23: 1 | AT23: 0 | AU23: 26 | AV23: 0 | AW23: 0 | AX23: 0 | AY23: 1 | AZ23: 20000000 | BA23: 0 | BC23: 0 | BE23: 0 | BG23: Sudrikah | BH23: SITI AISYAH | BI23: None | BJ23: https://build.fillout.com/editor/kdFWQQWTckus/results?sessionId=369b12fa-a078-4793-9170-6d973e1a24e1 | BK23: 87b2be06fe24b23c1179242f77cbe214
A24: 83fecf9c-4634-40c3-a478-df8cc368440e | B24: Wed May 13 2026 08:26:00 GMT+0700 (Western Indonesia Time) | C24: Tue May 12 2026 18:49:00 GMT+0700 (Western Indonesia Time) | D24: finished | E24: Ending | F24: 101 | G24: 2026-05-12 | H24: NABILAH MUAZAROH MOCHTAR | I24: Muhammad farianto | J24: 3515031008240005 | K24: https://prod-fillout-oregon-s3.s3.us-west-2.amazonaws.com/orgid-431168/flowpublicid-kdFWQQWTckus/6fc88ed8-9b9c-4da5-b3e6-1fef234e1c68-JoJ9wNEHuF59D4w45ax1EcUtp9jW0znPGnN5VQGM1BFdabaq1YMyKEKUMVaPRzc9YiK1Db3acnlLoM1Xurygd4AznGNhLXhLOgY/WA_1778586854330.jpg | L24: Nuryati | M24: Desa waung | N24: RT 001 RW 001 | O24: 1 | Q24: 2 | R24: 3 | U24: 100 | V24: 2 | W24: 1 | X24: 1 | Y24: 1 | Z24: 2 | AA24: 1 | AB24: 1 | AC24: 3 | AD24: 1 | AE24: 1 | AF24: 1 | AG24: 110 | AH24: 3 | AI24: 3 | AJ24: 3 | AK24: 3 | AL24: 200000 | AM24: 150000 | AN24: https://prod-fillout-oregon-s3.s3.us-west-2.amazonaws.com/orgid-431168/flowpublicid-kdFWQQWTckus/45bc4e42-ff53-4378-8cdc-44ddc9278d5c-bOJHwXJMrFejOrwgYFFCGqAvUAofhEyn7LQ3NzNjgETtkOxeK4LxyI85WK2EpXF7v0N8VF3DR3CEpSZ9wkvVJc9KGCkb2Y9YyPL/20260512_184047.jpg | AO24: https://prod-fillout-oregon-s3.s3.us-west-2.amazonaws.com/orgid-431168/flowpublicid-kdFWQQWTckus/0bbfde0d-5dfe-45d4-b1e8-bdbf2cb3ba76-UFPKolvhSSAzkNlHOvUjE4SuCMP2PFkzz14ypdKHSF1PZAKXUYELTFXO09zxeDsaCrZmJC48iVm03nH77129esLUZoOrFBqqp8x/20260512_184036.jpg | AP24: https://prod-fillout-oregon-s3.s3.us-west-2.amazonaws.com/orgid-431168/flowpublicid-kdFWQQWTckus/6dca5598-bf08-49ab-b015-188fa9d4928d-PbEU3non5UMoA1wd1XvLwaQ7kvP3I23G1wBqyS4KRsofEomrB5hjSpH1sEyTtogeW8GlhfEPDNh2FvSCzpwb8UzHx901PsiFpt8/20260512_184012.jpg | AQ24: 2 | AR24: 0 | AS24: 1 | AT24: 0 | AU24: 10 | AV24: 0 | AW24: 0 | AX24: 0 | AY24: 2 | AZ24: 23000000 | BA24: 1 | BB24: 70000000 | BC24: 0 | BE24: 0 | BG24: Muhammad farianto, Nuryati, Zahira faritania pandora | BH24: NABILAH MUAZAROH MOCHTAR | BI24: None | BJ24: https://build.fillout.com/editor/kdFWQQWTckus/results?sessionId=83fecf9c-4634-40c3-a478-df8cc368440e | BK24: 91d22f4714f303157d11716cb9588443
A25: c6166efc-8d63-44a9-9138-0b3ef3cfd5eb | B25: Wed May 13 2026 09:16:00 GMT+0700 (Western Indonesia Time) | C25: Tue May 12 2026 20:29:00 GMT+0700 (Western Indonesia Time) | D25: finished | E25: Ending | F25: 107 | G25: 2026-05-12 | H25: SRI WINARTI | I25: Kuswanto | J25: 3515031001093444 | K25: https://prod-fillout-oregon-s3.s3.us-west-2.amazonaws.com/orgid-431168/flowpublicid-kdFWQQWTckus/2c26a820-dbbd-4649-a4a6-37de88d2f363-02VmV5BNvmxs7R7SMU7JbSN6fvDApHtw04VUA8pX03tRbYYuyKsgwfg1CqV7vTF9Kq1e0t8LjKsrRKQt9DAxhIBuuPBheaiSqnh/IMG-20260512-WA0049.jpg | L25: Enny Heri Astutik | M25: Waung | N25: RT 007 RW 004 | O25: 1 | Q25: 1 | R25: 1 | S25: 1 | U25: 180 | V25: 2 | W25: 1 | X25: 1 | Y25: 1 | Z25: 2 | AA25: 1 | AB25: 1 | AC25: 1 | AD25: 1 | AE25: 7 | AF25: 1 | AG25: 1 | AH25: 2 | AL25: 250 | AM25: 150 | AN25: https://prod-fillout-oregon-s3.s3.us-west-2.amazonaws.com/orgid-431168/flowpublicid-kdFWQQWTckus/4cb29147-1f64-4c1b-820c-e5771b91156d-p07p2lHLxI0kjDs8t0dqMRrCgejUDUbWTXdFa5C77cw6dPrbB7GeqOGalvGvLeTsAspHMWSGAOrmnT4nlXmWT835DsmAqSJNVW1/1000421755.jpg | AO25: https://prod-fillout-oregon-s3.s3.us-west-2.amazonaws.com/orgid-431168/flowpublicid-kdFWQQWTckus/71353b7b-15b6-4b6c-bb16-f451cb908439-h1cvXukqGlTDEMXWrWjZiW38roi9iIHrPW6EKxWiCLRErqADr2jcglNBxT2uZefFmvxKJuvMhxR1KT2jOfX9wOhXQPoC3MSgunB/1000422400.jpg | AP25: https://prod-fillout-oregon-s3.s3.us-west-2.amazonaws.com/orgid-431168/flowpublicid-kdFWQQWTckus/d37ced23-8592-45ee-8579-bc4230c73678-JRipIsaWOGE10KzUVuFXVjk7zZdHvOwWJE580CKShHsr8FkYMgTuw732Cjo578VGWAX7lZPfuw3yesYXAyoFoJxpm1rTh90Fqbf/1000422403.jpg | AQ25: 2 | AR25: 0 | AS25: 1 | AT25: 0 | AU25: 10 | AV25: 0 | AW25: 2 | AX25: 0 | AY25: 2 | AZ25: 17000000 | BA25: 1 | BB25: 50000000 | BC25: 0 | BE25: 0 | BG25: Kuswanto, Enny Heri Astutik, Guntur Heri Kusnanda | BH25: SRI WINARTI | BI25: None | BJ25: https://build.fillout.com/editor/kdFWQQWTckus/results?sessionId=c6166efc-8d63-44a9-9138-0b3ef3cfd5eb | BK25: 04ffa5e8f3e8fbf982ef7ae5d8a41dbf
A26: 97e434a2-da36-4730-8101-910a1d95f7e4 | B26: Wed May 13 2026 09:42:00 GMT+0700 (Western Indonesia Time) | C26: Wed May 13 2026 09:17:00 GMT+0700 (Western Indonesia Time) | D26: finished | E26: Ending | F26: 107 | G26: 2026-05-13 | H26: SRI WINARTI | I26: Khoirul Anwar | J26: 3515031001093422 | K26: https://prod-fillout-oregon-s3.s3.us-west-2.amazonaws.com/orgid-431168/flowpublicid-kdFWQQWTckus/a9f74827-f02d-434a-9e25-8be45cbb219e-Q7vjoMkhh6pbMMahu16bPuEAFDqA6xMYq2XUn5WLHSubJ3RCjMGLi7ag9H8FJIJeN3sf9Btv7pmgYQwE17PLmICfg7MHI0dqW10/WA_1778637563552.jpg | L26: Indah Setyorini | M26: Waung | N26: RT 007 RW 004 | O26: 1 | Q26: 1 | R26: 1 | S26: 1 | U26: 150 | V26: 2 | W26: 1 | X26: 1 | Y26: 1 | Z26: 2 | AA26: 1 | AB26: 1 | AC26: 1 | AD26: 1 | AE26: 2 | AF26: 1 | AG26: 1 | AH26: 1 | AL26: 40000 | AM26: 200000 | AN26: https://prod-fillout-oregon-s3.s3.us-west-2.amazonaws.com/orgid-431168/flowpublicid-kdFWQQWTckus/c6cd3b00-1cd4-4201-9a04-3a58755d0e46-QSqlNKPVK59u1f04FJ0yOTbrx7o5hdwXgnDjPGUT0itUZzsYd9LY6SDj8ecUADh8BoqV4eK6Lz02kSh71ATF9cfo3iRZsQVcd6b/1000422898.jpg | AO26: https://prod-fillout-oregon-s3.s3.us-west-2.amazonaws.com/orgid-431168/flowpublicid-kdFWQQWTckus/d21424e6-cbb7-43df-8a79-761a05c3f3d2-66RRZWev4jxAkx9HAOn0AUXnq7wXZu5oqi7GVLomTl2dQAvbcpp81DhV4xA1vOu84ptW8ZpgylAjMBiZaB3nths7mktcLPHv0E0/1000422885.jpg | AP26: https://prod-fillout-oregon-s3.s3.us-west-2.amazonaws.com/orgid-431168/flowpublicid-kdFWQQWTckus/9335d369-7002-46ef-8778-a2b143cb5792-NGEEbk2fFOpBsWkUePWcAFHqJDfALJ8cIG6WBBnX7KkybFwF8W7V1gdUxAkor2NDe0d2EHN3UHLfDekg8j61njgKDho8NPjVYI8/1000422887.jpg | AQ26: 2 | AR26: 0 | AS26: 1 | AT26: 0 | AU26: 20 | AV26: 0 | AW26: 1 | AX26: 0 | AY26: 3 | AZ26: 14000000 | BA26: 0 | BC26: 0 | BE26: 0 | BG26: Khoirul Anwar, Endang Irawati, Indah Setyorini | BH26: SRI WINARTI | BI26: None | BJ26: https://build.fillout.com/editor/kdFWQQWTckus/results?sessionId=97e434a2-da36-4730-8101-910a1d95f7e4 | BK26: 04ffa5e8f3e8fbf982ef7ae5d8a41dbf
A27: 2f9e456a-114c-465b-9594-28b74ae58635 | B27: Wed May 13 2026 10:26:00 GMT+0700 (Western Indonesia Time) | C27: Wed May 13 2026 09:45:00 GMT+0700 (Western Indonesia Time) | D27: finished | E27: Ending | F27: 108 | G27: 2026-05-13 | H27: PRIYATNO | I27: teguh imam waskito | J27: 3515031001093509 | K27: https://prod-fillout-oregon-s3.s3.us-west-2.amazonaws.com/orgid-431168/flowpublicid-kdFWQQWTckus/857a7ab6-fbe9-4f7d-8ffe-d126efe4e3a9-9lsJEWD8at2RDwsUJAaGCUNu8THtg5NxzLVT5HH3qCYqEU7y3gpo8cOIDJTpAW2IqPPN1YetNJa2TeaMMXTfRcPXmTn9AZxFEUp/WA_1778640905213.jpg | L27: juma'ati | M27: waung | N27: RT 008 RW 004 | O27: 1 | Q27: 1 | R27: 1 | S27: 1 | U27: 80 | V27: 2 | W27: 1 | X27: 1 | Y27: 1 | Z27: 2 | AA27: 1 | AB27: 1 | AC27: 1 | AD27: 1 | AE27: 7 | AF27: 1 | AG27: 1 | AH27: 1 | AL27: 60000 | AM27: 250000 | AN27: https://prod-fillout-oregon-s3.s3.us-west-2.amazonaws.com/orgid-431168/flowpublicid-kdFWQQWTckus/f8b4700b-c319-434b-a07f-ddce5ad92c25-Qie6fLLj8DdPQjCgw5WDOv0kVj4s9pyOXV3sAIPV6s2IrVR5C9AboYyp7m0iY3TgBB0CJMTsMofMu6MMbha8W7Nz3dAMs0Rbi2a/WA_1778640514903.jpg | AO27: https://prod-fillout-oregon-s3.s3.us-west-2.amazonaws.com/orgid-431168/flowpublicid-kdFWQQWTckus/c8d11d11-54dc-4266-97e4-dd38f222ddad-vusu67L9uX52DNacdcjDc1sjy4o7NY2nw2akGcpifqsuz8zKqi0Emxs6cxnV5SZFtbo21DhG6rBBeu2tkwXzwXNzOa2bJlGPPDe/WA_1778640545395.jpg | AP27: https://prod-fillout-oregon-s3.s3.us-west-2.amazonaws.com/orgid-431168/flowpublicid-kdFWQQWTckus/a15fe92e-6185-4288-9b27-0ba311835c44-xPJxWAyGkT9aUbWbwaar79W1L8Nj6tMFpnPRsXHuhDqXkvwAvrCjzg2FvOp3yvAZcL64ZghjDekYuFb73OLNOnH8WfXE3FtZgZM/WA_1778640568540.jpg | AQ27: 2 | AR27: 0 | AS27: 1 | AT27: 0 | AU27: 2 | AV27: 0 | AW27: 2 | AX27: 0 | AY27: 3 | AZ27: 15000000 | BA27: 1 | BB27: 80000000 | BC27: 0 | BE27: 0 | BG27: teguh imam waskito, juma'ati, Mohammad Bayu Nanda waskito, Denny Dwi waskito, Muhammad risky tri waskito | BH27: PRIYATNO | BI27: None | BJ27: https://build.fillout.com/editor/kdFWQQWTckus/results?sessionId=2f9e456a-114c-465b-9594-28b74ae58635 | BK27: 04185b05bdb233ac9e644c693e2681dc
A28: 541cfc59-5f2f-4de6-bb30-50d30610eaa4 | B28: Wed May 13 2026 10:37:00 GMT+0700 (Western Indonesia Time) | C28: Wed May 13 2026 09:56:00 GMT+0700 (Western Indonesia Time) | D28: finished | E28: Ending | F28: 107 | G28: 2026-05-13 | H28: SRI WINARTI | I28: Kariyono | J28: 3515031001093462 | K28: https://prod-fillout-oregon-s3.s3.us-west-2.amazonaws.com/orgid-431168/flowpublicid-kdFWQQWTckus/6d69c831-e60c-4983-b06a-3aa4e39fea5d-UFJTRaigR040iKULlUlYoprCl7ZTRb0Hxtcfw3euEF7laOxSiuz3qCA3gfUU115LjD9lBoQT0AxdGGg5JYDYMKLvaTzrGRcEMkF/WA_1778637610348.jpg | L28: Sunarkom | M28: Waung | N28: RT 007 RW 004 | O28: 1 | Q28: 2 | R28: 1 | S28: 1 | U28: 50 | V28: 2 | W28: 1 | X28: 1 | Y28: 1 | Z28: 2 | AA28: 1 | AB28: 1 | AC28: 1 | AD28: 1 | AE28: 2 | AF28: 1 | AG28: 1 | AH28: 2 | AL28: 75000 | AM28: 50000 | AN28: https://prod-fillout-oregon-s3.s3.us-west-2.amazonaws.com/orgid-431168/flowpublicid-kdFWQQWTckus/feeb6bfb-b38f-4f9e-9b9a-bab3cd5124b5-s3WfSWewi6EYQQJ9JSwLAy7zSeEeOS718b6m9ZE2hiBbfTkLRyoaJExfna6MQyZ2vLKj3Z62mhjAWalFOhuBqps4dqljYgmdTXD/1000422984.jpg | AO28: https://prod-fillout-oregon-s3.s3.us-west-2.amazonaws.com/orgid-431168/flowpublicid-kdFWQQWTckus/46989b71-eb12-4e74-b5d2-aa403a2eeea9-MEtzzjQKpPM8C946V8YcGe8giVzhrbwNTGen7OPMnc2kN81cH17GDsPpdR6jWAmUK1wOd1OW8cc9cxf0Aki3LT8G9d2o3dE7iVl/1000422940.jpg | AP28: https://prod-fillout-oregon-s3.s3.us-west-2.amazonaws.com/orgid-431168/flowpublicid-kdFWQQWTckus/1072e161-d128-4966-8e09-d61faff41cde-bcbhIIXgUupts7PBUsMxkRsLWkSMhuhKe0l6q0Jk0jeHvS8arDqvA6i3lVwxcMCxABVNwkynjg1aNhwaiQXx9W1OOCRd9GHBRGI/1000422990.jpg | AQ28: 2 | AR28: 0 | AS28: 1 | AT28: 0 | AU28: 0 | AV28: 0 | AW28: 2 | AX28: 0 | AY28: 1 | AZ28: 3000000 | BA28: 0 | BC28: 0 | BE28: 0 | BG28: Kariyono, Sunarkom | BH28: SRI WINARTI | BI28: None | BJ28: https://build.fillout.com/editor/kdFWQQWTckus/results?sessionId=541cfc59-5f2f-4de6-bb30-50d30610eaa4 | BK28: 04ffa5e8f3e8fbf982ef7ae5d8a41dbf
A29: 5330375f-40aa-43c5-a987-6760e7cdc8df | B29: Wed May 13 2026 11:05:00 GMT+0700 (Western Indonesia Time) | C29: Wed May 13 2026 10:38:00 GMT+0700 (Western Indonesia Time) | D29: finished | E29: Ending | F29: 107 | G29: 2026-05-13 | H29: SRI WINARTI | I29: Masrul Abidin A.A | J29: 3515031402170004 | K29: https://prod-fillout-oregon-s3.s3.us-west-2.amazonaws.com/orgid-431168/flowpublicid-kdFWQQWTckus/5f3c7a77-83dd-49d8-a1eb-048963788496-0nbdHcLmCyiZ8Xe1VZZHVrhfdQIFochvnYu1NjCyaEpAoJuMx23qnuX7gRTZhQKNAtPJRZbC0lxDwYh4z0l2fzSDwD05o7QSRwn/WA_1778637655519.jpg | L29: Tri Harumil | M29: Waung | N29: RT 007 RW 004 | O29: 1 | Q29: 2 | R29: 3 | U29: 50 | V29: 2 | W29: 1 | X29: 1 | Y29: 1 | Z29: 2 | AA29: 1 | AB29: 1 | AC29: 1 | AD29: 1 | AE29: 2 | AF29: 2 | AL29: 75000 | AM29: 50000 | AN29: https://prod-fillout-oregon-s3.s3.us-west-2.amazonaws.com/orgid-431168/flowpublicid-kdFWQQWTckus/e31fbbb7-9cff-49ae-8a7a-528730c5151c-jWOpwwtWbnz0y7xg8cgICKnChVCUtpYKPcBSgWsn2GSmlo3Eb9g0t7ImBInpLspQobt1gxoQzbFCXvlLqXL5NT35WyuVF9n2ApX/1000422984.jpg | AO29: https://prod-fillout-oregon-s3.s3.us-west-2.amazonaws.com/orgid-431168/flowpublicid-kdFWQQWTckus/2b463ff6-f352-4f5c-93f6-95c143d37016-HwfJbIk642fraUSFm7tScqCgk1rcK9ig3MA6WqtsPUFnGF0yGH1VTXOY08HKjzKgvQ3dAYrop9zdGV4E8nGe44RC584xngmCwXx/1000422940.jpg | AP29: https://prod-fillout-oregon-s3.s3.us-west-2.amazonaws.com/orgid-431168/flowpublicid-kdFWQQWTckus/4b278e6c-f20c-4772-94f8-7c34a5b334ee-0oVGITneOFSJlcGauvAdbGMzRz6Fe0dkaMocGVBMzv3vfOg8EdnudNeQPN9QL3kD0eaHp7qF7d0gJANANbAMrJyAkteKiPFVleY/1000422990.jpg | AQ29: 0 | AR29: 0 | AS29: 0 | AT29: 0 | AU29: 0 | AV29: 0 | AW29: 1 | AX29: 0 | AY29: 1 | AZ29: 8000000 | BA29: 0 | BC29: 0 | BE29: 0 | BG29: Masrul Abidin A.A, Tri Harumil, Muhammmad Azka Al Achyar, Muhammmad Davian Revano | BH29: SRI WINARTI | BI29: None | BJ29: https://build.fillout.com/editor/kdFWQQWTckus/results?sessionId=5330375f-40aa-43c5-a987-6760e7cdc8df | BK29: 2ed216414a105846b4520f43e8c94ae1
